Workbook

Sheet 测算主页
A1: 储能电站「谷充峰放」套利收益测算模型 v2.0
A2: 基于陕西省一般工商业分时电价 | 含IRR/NPV/多维度敏感性分析
A4: ▎输入参数（修改蓝色区域数值，所有结果自动更新）
A6: 【电价参数】
A8: 峰段电价（元/kWh） | C8: 1.2 | E8: 陕西一般工商业峰段
A9: 谷段电价（元/kWh） | C9: 0.3 | E9: 陕西一般工商业谷段
A10: 平时段电价（元/kWh） | C10: 0.65 | E10: 参考值·平段不参与套利
A11: 峰谷价差（元/kWh） | C11: =B8-B9 | E11: =峰段-谷段，自动计算
A13: 【储能系统参数】
A15: 额定容量（MWh） | C15: 100 | E15: 交流侧可用容量
A16: 充放电综合效率（RTE） | C16: 0.9 | E16: 往返效率=放电量/充电量
A17: 其中：充电效率 | C17: =SQRT(B16) | E17: =√RTE，自动计算
A18: 其中：放电效率 | C18: =SQRT(B16) | E18: =√RTE，自动计算
A19: 放电深度（DoD） | C19: 0.95 | E19: 实际可用容量比例
A20: 循环寿命（次） | C20: 5000 | E20: 至容量衰减至80%
A21: 年容量衰减率 | C21: 0.02 | E21: 日历+循环老化综合
A23: 【运营参数】
A25: 每日循环次数 | C25: 1 | E25: 谷充峰放=1次完整循环
A26: 年运营天数 | C26: 330 | E26: 扣除检修停机约35天
A27: 年循环次数 | C27: =B25*B26 | E27: =每日次数×年天数
A28: 项目运营年限 | C28: 10 | E28: 测算周期
A30: 【投资与财务参数】
A32: 单位投资成本（元/Wh） | C32: 1.8 | E32: 行业区间1.5-2.0元/Wh
A33: 初始总投资（万元） | C33: =B15*B32*100 | E33: =容量MWh×投资元/Wh×100
A34: 年运维费率 | C34: 0.02 | E34: 占初始投资比例
A35: 折现率（WACC） | C35: 0.08 | E35: 加权平均资本成本
A36: 企业所得税率 | C36: 0.25 | E36: 用于净利润计算·可设为0忽略
A38: ▎单次循环收益测算（第1年，无衰减，以100MWh容量为基准）
A40: 有效可用容量（kWh） | C40: =B15*1000*B19 | E40: =B15*1000*B19 | F40: kWh | G40: 额定容量×1000×DoD
A41: 充电量·电网取电（kWh） | C41: =B40/B17 | E41: =B40/B17 | F41: kWh | G41: 有效容量÷充电效率（含损耗）
A42: 充电成本（万元） | C42: =B41*B9/10000 | E42: =B41*B9/10000 | F42: 万元 | G42: 充电量×谷段电价÷10000
A43: 放电量·上网售电（kWh） | C43: =B40*B18 | E43: =B40*B18 | F43: kWh | G43: 有效容量×放电效率（含损耗）
A44: 放电收入（万元） | C44: =B43*B8/10000 | E44: =B43*B8/10000 | F44: 万元 | G44: 放电量×峰段电价÷10000
A45: 单次循环毛利（万元） | C45: =B44-B42 | E45: =B44-B42 | F45: 万元 | G45: 放电收入-充电成本
A46: 单次循环毛利率 | C46: =B45/B44 | E46: =B45/B44 | F46: % | G46: 毛利÷收入
A48: ▎年度收益汇总 & 核心财务指标（第1年为基准）
A49: 年循环次数（次） | C49: =B27 | E49: =B27 | F49: 次 | G49: 谷充峰放循环
A50: 年充电总成本（万元） | C50: =B42*B49 | E50: =B42*B49 | F50: 万元 | G50: 单次成本×循环次数
A51: 年放电总收入（万元） | C51: =B44*B49 | E51: =B44*B49 | F51: 万元 | G51: 单次收入×循环次数
A52: 年毛利（万元） | C52: =B51-B50 | E52: =B51-B50 | F52: 万元 | G52: 收入-成本
...

Sheet 逐年收益表
A1: 10年逐年收益测算明细
A2: 考虑容量衰减 + 充放电效率不变 + 电价不变
A4: 年份 | B4: 有效容量 (MWh) | C4: 有效容量 (kWh) | D4: 单次充电 成本(万元) | E4: 单次放电 收入(万元) | F4: 单次毛利 (万元) | G4: 年循环 次数 | H4: 年度毛利 (万元) | I4: 累计毛利 (万元)
A5: 第1年 | B5: ='测算主页'!B15*'测算主页'!B19 | C5: =B5*1000 | D5: ='测算主页'!B9*C5/'测算主页'!B17/10000 | E5: ='测算主页'!B8*C5*'测算主页'!B18/10000 | F5: =E5-D5 | G5: ='测算主页'!B27 | H5: =F5*G5 | I5: =H5
A6: 第2年 | B6: =B5*(1-'测算主页'!B21) | C6: =B6*1000 | D6: ='测算主页'!B9*C6/'测算主页'!B17/10000 | E6: ='测算主页'!B8*C6*'测算主页'!B18/10000 | F6: =E6-D6 | G6: ='测算主页'!B27 | H6: =F6*G6 | I6: =I5+H6
A7: 第3年 | B7: =B6*(1-'测算主页'!B21) | C7: =B7*1000 | D7: ='测算主页'!B9*C7/'测算主页'!B17/10000 | E7: ='测算主页'!B8*C7*'测算主页'!B18/10000 | F7: =E7-D7 | G7: ='测算主页'!B27 | H7: =F7*G7 | I7: =I6+H7
A8: 第4年 | B8: =B7*(1-'测算主页'!B21) | C8: =B8*1000 | D8: ='测算主页'!B9*C8/'测算主页'!B17/10000 | E8: ='测算主页'!B8*C8*'测算主页'!B18/10000 | F8: =E8-D8 | G8: ='测算主页'!B27 | H8: =F8*G8 | I8: =I7+H8
A9: 第5年 | B9: =B8*(1-'测算主页'!B21) | C9: =B9*1000 | D9: ='测算主页'!B9*C9/'测算主页'!B17/10000 | E9: ='测算主页'!B8*C9*'测算主页'!B18/10000 | F9: =E9-D9 | G9: ='测算主页'!B27 | H9: =F9*G9 | I9: =I8+H9
A10: 第6年 | B10: =B9*(1-'测算主页'!B21) | C10: =B10*1000 | D10: ='测算主页'!B9*C10/'测算主页'!B17/10000 | E10: ='测算主页'!B8*C10*'测算主页'!B18/10000 | F10: =E10-D10 | G10: ='测算主页'!B27 | H10: =F10*G10 | I10: =I9+H10
A11: 第7年 | B11: =B10*(1-'测算主页'!B21) | C11: =B11*1000 | D11: ='测算主页'!B9*C11/'测算主页'!B17/10000 | E11: ='测算主页'!B8*C11*'测算主页'!B18/10000 | F11: =E11-D11 | G11: ='测算主页'!B27 | H11: =F11*G11 | I11: =I10+H11
A12: 第8年 | B12: =B11*(1-'测算主页'!B21) | C12: =B12*1000 | D12: ='测算主页'!B9*C12/'测算主页'!B17/10000 | E12: ='测算主页'!B8*C12*'测算主页'!B18/10000 | F12: =E12-D12 | G12: ='测算主页'!B27 | H12: =F12*G12 | I12: =I11+H12
A13: 第9年 | B13: =B12*(1-'测算主页'!B21) | C13: =B13*1000 | D13: ='测算主页'!B9*C13/'测算主页'!B17/10000 | E13: ='测算主页'!B8*C13*'测算主页'!B18/10000 | F13: =E13-D13 | G13: ='测算主页'!B27 | H13: =F13*G13 | I13: =I12+H13
A14: 第10年 | B14: =B13*(1-'测算主页'!B21) | C14: =B14*1000 | D14: ='测算主页'!B9*C14/'测算主页'!B17/10000 | E14: ='测算主页'!B8*C14*'测算主页'!B18/10000 | F14: =E14-D14 | G14: ='测算主页'!B27 | H14: =F14*G14 | I14: =I13+H14
A15: 10年合计 | H15: =SUM(H6:H15)

Sheet 现金流与IRR
A1: 全周期现金流分析：IRR / NPV / 投资回收期
A2: 自由现金流 = 毛利 - 运维费 - 所得税 | 折现率引用自测算主页
A4: 年份 | B4: 年度毛利 (万元) | C4: 运维费 (万元) | D4: 税前利润 (万元) | E4: 所得税 (万元) | F4: 自由现金流 (万元) | G4: 折现因子 | H4: 折现现金流 (万元)
A5: 第0年（投资） | B5: 0 | C5: 0 | D5: 0 | E5: 0 | F5: =-'测算主页'!B33 | G5: 1 | H5: =F5*G5 | I5: =H5
A6: 第1年 | B6: ='逐年收益表'!H5 | C6: ='测算主页'!B33*'测算主页'!B34 | D6: =B6-C6 | E6: =D6*'测算主页'!B36 | F6: =D6-E6 | G6: =1/(1+'测算主页'!B35)^1 | H6: =F6*G6 | I6: =I5+H6
A7: 第2年 | B7: ='逐年收益表'!H6 | C7: ='测算主页'!B33*'测算主页'!B34 | D7: =B7-C7 | E7: =D7*'测算主页'!B36 | F7: =D7-E7 | G7: =1/(1+'测算主页'!B35)^2 | H7: =F7*G7 | I7: =I6+H7
A8: 第3年 | B8: ='逐年收益表'!H7 | C8: ='测算主页'!B33*'测算主页'!B34 | D8: =B8-C8 | E8: =D8*'测算主页'!B36 | F8: =D8-E8 | G8: =1/(1+'测算主页'!B35)^3 | H8: =F8*G8 | I8: =I7+H8
A9: 第4年 | B9: ='逐年收益表'!H8 | C9: ='测算主页'!B33*'测算主页'!B34 | D9: =B9-C9 | E9: =D9*'测算主页'!B36 | F9: =D9-E9 | G9: =1/(1+'测算主页'!B35)^4 | H9: =F9*G9 | I9: =I8+H9
A10: 第5年 | B10: ='逐年收益表'!H9 | C10: ='测算主页'!B33*'测算主页'!B34 | D10: =B10-C10 | E10: =D10*'测算主页'!B36 | F10: =D10-E10 | G10: =1/(1+'测算主页'!B35)^5 | H10: =F10*G10 | I10: =I9+H10
A11: 第6年 | B11: ='逐年收益表'!H10 | C11: ='测算主页'!B33*'测算主页'!B34 | D11: =B11-C11 | E11: =D11*'测算主页'!B36 | F11: =D11-E11 | G11: =1/(1+'测算主页'!B35)^6 | H11: =F11*G11 | I11: =I10+H11
A12: 第7年 | B12: ='逐年收益表'!H11 | C12: ='测算主页'!B33*'测算主页'!B34 | D12: =B12-C12 | E12: =D12*'测算主页'!B36 | F12: =D12-E12 | G12: =1/(1+'测算主页'!B35)^7 | H12: =F12*G12 | I12: =I11+H12
A13: 第8年 | B13: ='逐年收益表'!H12 | C13: ='测算主页'!B33*'测算主页'!B34 | D13: =B13-C13 | E13: =D13*'测算主页'!B36 | F13: =D13-E13 | G13: =1/(1+'测算主页'!B35)^8 | H13: =F13*G13 | I13: =I12+H13
A14: 第9年 | B14: ='逐年收益表'!H13 | C14: ='测算主页'!B33*'测算主页'!B34 | D14: =B14-C14 | E14: =D14*'测算主页'!B36 | F14: =D14-E14 | G14: =1/(1+'测算主页'!B35)^9 | H14: =F14*G14 | I14: =I13+H14
A15: 第10年 | B15: ='逐年收益表'!H14 | C15: ='测算主页'!B33*'测算主页'!B34 | D15: =B15-C15 | E15: =D15*'测算主页'!B36 | F15: =D15-E15 | G15: =1/(1+'测算主页'!B35)^10 | H15: =F15*G15 | I15: =I14+H15
A16: 合计 | B16: =SUM(B6:B15) | C16: =SUM(C6:C15) | D16: =SUM(D6:D15) | E16: =SUM(E6:E15) | F16: =SUM(F6:F15) | H16: =SUM(H6:H15)
A18: 财务指标 | C18: 计算公式 | F18: 数值
A19: 累计自由现金流（万元） | C19: =SUM(F6:F15) | F19: =SUM(F6:F15)
A20: 初始总投资（万元） | C20: ='测算主页'!B33 | F20: ='测算主页'!B33
A21: IRR·内部收益率 | C21: =IRR(F5:F15,0.1) | F21: =IRR(F5:F15,0.1)
A22: NPV·净现值（万元） | C22: =NPV('测算主页'!B35,F6:F15)+F5 | F22: =NPV('测算主页'!B35,F6:F15)+F5
A23: NPV不含投资（万元） | C23: =NPV('测算主页'!B35,F6:F15) | F23: =NPV('测算主页'!B35,F6:F15)
A24: 静态回收期（年） | C24: ='测算主页'!B33/AVERAGE(F6:F15) | F24: ='测算主页'!B33/AVERAGE(F6:F15)
A25: 动态回收期（年） | C25: =B23/(B25/B33) | F25: =B23/(B25/B33)
A28: 累计DCF

Sheet 敏感性分析
A1: 多维度敏感性分析：龙卷风图 + 价差×效率矩阵 + 蜘蛛图
A3: ▎龙卷风图：各变量对NPV的影响幅度（基于当前基准参数预计算）
A4: 说明：以下为Python端基于当前测算主页参数预计算的结果。修改基准参数后需重新运行脚本更新。
A6: 变量 | B6: 低值 | C6: 高值 | D6: NPV@低值 (万元) | E6: NPV@高值 (万元) | F6: NPV变化 (万元) | G6: NPV变化% | H6: IRR@低值 | I6: IRR@高值 | J6: IRR变化
A7: 峰谷价差 | B7: 0.72 | C7: 1.08 | D7: -7054.3425 | E7: -49.396092 | F7: 7004.9465 | G7: -1.9721859 | H7: -0.020938011 | I7: 0.079367595 | J7: 0.10030561
A8: 单位投资成本 | B8: 1.53 | C8: 2.07 | D8: -489.52492 | E8: -6614.2137 | F8: -6124.6888 | G8: 1.7243565 | H8: 0.072578295 | I8: -0.00021684949 | J8: -0.072795145
A9: 折现率 | B9: 0.05 | C9: 0.11 | D9: -1462.0552 | E9: -5254.9468 | F9: -3792.8916 | G9: 1.0678579 | H9: 0.032277032 | I9: 0.032277032 | J9: 0
A10: 年运营天数 | B10: 297 | C10: 363 | D10: -5238.2453 | E10: -1865.4933 | F10: 3372.752 | G10: -0.94957097 | H10: 0.0076186534 | I10: 0.05554663 | J10: 0.047927976
A11: 充放电效率 | B11: 0.84 | C11: 0.96 | D11: -4571.2701 | E11: -2580.1394 | F11: 1991.1307 | G11: -0.5605867 | H11: 0.017558917 | I11: 0.045835414 | J11: 0.028276497
A12: 年衰减率 | B12: 0.01 | C12: 0.03 | D12: -2897.2975 | E12: -4174.9505 | F12: -1277.653 | G12: 0.35971284 | H12: 0.042163314 | I12: 0.022284219 | J12: -0.019879095
A13: 基准NPV = -3552万元 | 基准IRR = 3.2%
A15: 变量 | B15: NPV降低 | C15: NPV增加
A16: 峰谷价差 | B16: -3502.4732 | C16: 3502.4732
A17: 单位投资成本 | B17: 3062.3444 | C17: -3062.3444
A18: 折现率 | B18: 2089.8141 | C18: -1703.0775
A19: 年运营天数 | B19: -1686.376 | C19: 1686.376
A20: 充放电效率 | B20: -1019.4008 | C20: 971.72991
A21: 年衰减率 | B21: 654.57183 | C21: -623.08116
A42: ▎价差×效率二维敏感性矩阵：第1年毛利（万元）— 公式动态计算
A44: 价差变化 ↓ \ 效率 → | B44: 0.84 | C44: 0.86 | D44: 0.88 | E44: 0.9 | F44: 0.92 | G44: 0.94 | H44: 0.96
A45: ← 价差越小→毛利越低 | B45: =(('测算主页'!B9+'测算主页'!B11*(1+A45))*'测算主页'!B15*1000*'测算主页'!B19*SQRT(0.84)-'测算主页'!B9*'测算主页'!B15*1000*'测算主页'!B19/SQRT(0.84))*'测算主页'!B27/10000 | C45: =(('测算主页'!B9+'测算主页'!B11*(1+A45))*'测算主页'!B15*1000*'测算主页'!B19*SQRT(0.86)-'测算主页'!B9*'测算主页'!B15*1000*'测算主页'!B19/SQRT(0.86))*'测算主页'!B27/10000 | D45: =(('测算主页'!B9+'测算主页'!B11*(1+A45))*'测算主页'!B15*1000*'测算主页'!B19*SQRT(0.88)-'测算主页'!B9*'测算主页'!B15*1000*'测算主页'!B19/SQRT(0.88))*'测算主页'!B27/10000 | E45: =(('测算主页'!B9+'测算主页'!B11*(1+A45))*'测算主页'!B15*1000*'测算主页'!B19*SQRT(0.9)-'测算主页'!B9*'测算主页'!B15*1000*'测算主页'!B19/SQRT(0.9))*'测算主页'!B27/10000 | F45: =(('测算主页'!B9+'测算主页'!B11*(1+A45))*'测算主页'!B15*1000*'测算主页'!B19*SQRT(0.92)-'测算主页'!B9*'测算主页'!B15*1000*'测算主页'!B19/SQRT(0.92))*'测算主页'!B27/10000 | G45: =(('测算主页'!B9+'测算主页'!B11*(1+A45))*'测算主页'!B15*1000*'测算主页'!B19*SQRT(0.94)-'测算主页'!B9*'测算主页'!B15*1000*'测算主页'!B19/SQRT(0.94))*'测算主页'!B27/10000 | H45: =(('测算主页'!B9+'测算主页'!B11*(1+A45))*'测算主页'!B15*1000*'测算主页'!B19*SQRT(0.96)-'测算主页'!B9*'测算主页'!B15*1000*'测算主页'!B19/SQRT(0.96))*'测算主页'!B27/10000
A46: -15% | B46: =(('测算主页'!B9+'测算主页'!B11*(1+A46))*'测算主页'!B15*1000*'测算主页'!B19*SQRT(0.84)-'测算主页'!B9*'测算主页'!B15*1000*'测算主页'!B19/SQRT(0.84))*'测算主页'!B27/10000 | C46: =(('测算主页'!B9+'测算主页'!B11*(1+A46))*'测算主页'!B15*1000*'测算主页'!B19*SQRT(0.86)-'测算主页'!B9*'测算主页'!B15*1000*'测算主页'!B19/SQRT(0.86))*'测算主页'!B27/10000 | D46: =(('测算主页'!B9+'测算主页'!B11*(1+A46))*'测算主页'!B15*1000*'测算主页'!B19*SQRT(0.88)-'测算主页'!B9*'测算主页'!B15*1000*'测算主页'!B19/SQRT(0.88))*'测算主页'!B27/10000 | E46: =(('测算主页'!B9+'测算主页'!B11*(1+A46))*'测算主页'!B15*1000*'测算主页'!B19*SQRT(0.9)-'测算主页'!B9*'测算主页'!B15*1000*'测算主页'!B19/SQRT(0.9))*'测算主页'!B27/10000 | F46: =(('测算主页'!B9+'测算主页'!B11*(1+A46))*'测算主页'!B15*1000*'测算主页'!B19*SQRT(0.92)-'测算主页'!B9*'测算主页'!B15*1000*'测算主页'!B19/SQRT(0.92))*'测算主页'!B27/10000 | G46: =(('测算主页'!B9+'测算主页'!B11*(1+A46))*'测算主页'!B15*1000*'测算主页'!B19*SQRT(0.94)-'测算主页'!B9*'测算主页'!B15*1000*'测算主页'!B19/SQRT(0.94))*'测算主页'!B27/10000 | H46: =(('测算主页'!B9+'测算主页'!B11*(1+A46))*'测算主页'!B15*1000*'测算主页'!B19*SQRT(0.96)-'测算主页'!B9*'测算主页'!B15*1000*'测算主页'!B19/SQRT(0.96))*'测算主页'!B27/10000
A47: -10% | B47: =(('测算主页'!B9+'测算主页'!B11*(1+A47))*'测算主页'!B15*1000*'测算主页'!B19*SQRT(0.84)-'测算主页'!B9*'测算主页'!B15*1000*'测算主页'!B19/SQRT(0.84))*'测算主页'!B27/10000 | C47: =(('测算主页'!B9+'测算主页'!B11*(1+A47))*'测算主页'!B15*1000*'测算主页'!B19*SQRT(0.86)-'测算主页'!B9*'测算主页'!B15*1000*'测算主页'!B19/SQRT(0.86))*'测算主页'!B27/10000 | D47: =(('测算主页'!B9+'测算主页'!B11*(1+A47))*'测算主页'!B15*1000*'测算主页'!B19*SQRT(0.88)-'测算主页'!B9*'测算主页'!B15*1000*'测算主页'!B19/SQRT(0.88))*'测算主页'!B27/10000 | E47: =(('测算主页'!B9+'测算主页'!B11*(1+A47))*'测算主页'!B15*1000*'测算主页'!B19*SQRT(0.9)-'测算主页'!B9*'测算主页'!B15*1000*'测算主页'!B19/SQRT(0.9))*'测算主页'!B27/10000 | F47: =(('测算主页'!B9+'测算主页'!B11*(1+A47))*'测算主页'!B15*1000*'测算主页'!B19*SQRT(0.92)-'测算主页'!B9*'测算主页'!B15*1000*'测算主页'!B19/SQRT(0.92))*'测算主页'!B27/10000 | G47: =(('测算主页'!B9+'测算主页'!B11*(1+A47))*'测算主页'!B15*1000*'测算主页'!B19*SQRT(0.94)-'测算主页'!B9*'测算主页'!B15*1000*'测算主页'!B19/SQRT(0.94))*'测算主页'!B27/10000 | H47: =(('测算主页'!B9+'测算主页'!B11*(1+A47))*'测算主页'!B15*1000*'测算主页'!B19*SQRT(0.96)-'测算主页'!B9*'测算主页'!B15*1000*'测算主页'!B19/SQRT(0.96))*'测算主页'!B27/10000
A48: -5% | B48: =(('测算主页'!B9+'测算主页'!B11*(1+A48))*'测算主页'!B15*1000*'测算主页'!B19*SQRT(0.84)-'测算主页'!B9*'测算主页'!B15*1000*'测算主页'!B19/SQRT(0.84))*'测算主页'!B27/10000 | C48: =(('测算主页'!B9+'测算主页'!B11*(1+A48))*'测算主页'!B15*1000*'测算主页'!B19*SQRT(0.86)-'测算主页'!B9*'测算主页'!B15*1000*'测算主页'!B19/SQRT(0.86))*'测算主页'!B27/10000 | D48: =(('测算主页'!B9+'测算主页'!B11*(1+A48))*'测算主页'!B15*1000*'测算主页'!B19*SQRT(0.88)-'测算主页'!B9*'测算主页'!B15*1000*'测算主页'!B19/SQRT(0.88))*'测算主页'!B27/10000 | E48: =(('测算主页'!B9+'测算主页'!B11*(1+A48))*'测算主页'!B15*1000*'测算主页'!B19*SQRT(0.9)-'测算主页'!B9*'测算主页'!B15*1000*'测算主页'!B19/SQRT(0.9))*'测算主页'!B27/10000 | F48: =(('测算主页'!B9+'测算主页'!B11*(1+A48))*'测算主页'!B15*1000*'测算主页'!B19*SQRT(0.92)-'测算主页'!B9*'测算主页'!B15*1000*'测算主页'!B19/SQRT(0.92))*'测算主页'!B27/10000 | G48: =(('测算主页'!B9+'测算主页'!B11*(1+A48))*'测算主页'!B15*1000*'测算主页'!B19*SQRT(0.94)-'测算主页'!B9*'测算主页'!B15*1000*'测算主页'!B19/SQRT(0.94))*'测算主页'!B27/10000 | H48: =(('测算主页'!B9+'测算主页'!B11*(1+A48))*'测算主页'!B15*1000*'测算主页'!B19*SQRT(0.96)-'测算主页'!B9*'测算主页'!B15*1000*'测算主页'!B19/SQRT(0.96))*'测算主页'!B27/10000
A49: +0% | B49: =(('测算主页'!B9+'测算主页'!B11*(1+A49))*'测算主页'!B15*1000*'测算主页'!B19*SQRT(0.84)-'测算主页'!B9*'测算主页'!B15*1000*'测算主页'!B19/SQRT(0.84))*'测算主页'!B27/10000 | C49: =(('测算主页'!B9+'测算主页'!B11*(1+A49))*'测算主页'!B15*1000*'测算主页'!B19*SQRT(0.86)-'测算主页'!B9*'测算主页'!B15*1000*'测算主页'!B19/SQRT(0.86))*'测算主页'!B27/10000 | D49: =(('测算主页'!B9+'测算主页'!B11*(1+A49))*'测算主页'!B15*1000*'测算主页'!B19*SQRT(0.88)-'测算主页'!B9*'测算主页'!B15*1000*'测算主页'!B19/SQRT(0.88))*'测算主页'!B27/10000 | E49: =(('测算主页'!B9+'测算主页'!B11*(1+A49))*'测算主页'!B15*1000*'测算主页'!B19*SQRT(0.9)-'测算主页'!B9*'测算主页'!B15*1000*'测算主页'!B19/SQRT(0.9))*'测算主页'!B27/10000 | F49: =(('测算主页'!B9+'测算主页'!B11*(1+A49))*'测算主页'!B15*1000*'测算主页'!B19*SQRT(0.92)-'测算主页'!B9*'测算主页'!B15*1000*'测算主页'!B19/SQRT(0.92))*'测算主页'!B27/10000 | G49: =(('测算主页'!B9+'测算主页'!B11*(1+A49))*'测算主页'!B15*1000*'测算主页'!B19*SQRT(0.94)-'测算主页'!B9*'测算主页'!B15*1000*'测算主页'!B19/SQRT(0.94))*'测算主页'!B27/10000 | H49: =(('测算主页'!B9+'测算主页'!B11*(1+A49))*'测算主页'!B15*1000*'测算主页'!B19*SQRT(0.96)-'测算主页'!B9*'测算主页'!B15*1000*'测算主页'!B19/SQRT(0.96))*'测算主页'!B27/10000 | J49: 基准组合
A50: +5% | B50: =(('测算主页'!B9+'测算主页'!B11*(1+A50))*'测算主页'!B15*1000*'测算主页'!B19*SQRT(0.84)-'测算主页'!B9*'测算主页'!B15*1000*'测算主页'!B19/SQRT(0.84))*'测算主页'!B27/10000 | C50: =(('测算主页'!B9+'测算主页'!B11*(1+A50))*'测算主页'!B15*1000*'测算主页'!B19*SQRT(0.86)-'测算主页'!B9*'测算主页'!B15*1000*'测算主页'!B19/SQRT(0.86))*'测算主页'!B27/10000 | D50: =(('测算主页'!B9+'测算主页'!B11*(1+A50))*'测算主页'!B15*1000*'测算主页'!B19*SQRT(0.88)-'测算主页'!B9*'测算主页'!B15*1000*'测算主页'!B19/SQRT(0.88))*'测算主页'!B27/10000 | E50: =(('测算主页'!B9+'测算主页'!B11*(1+A50))*'测算主页'!B15*1000*'测算主页'!B19*SQRT(0.9)-'测算主页'!B9*'测算主页'!B15*1000*'测算主页'!B19/SQRT(0.9))*'测算主页'!B27/10000 | F50: =(('测算主页'!B9+'测算主页'!B11*(1+A50))*'测算主页'!B15*1000*'测算主页'!B19*SQRT(0.92)-'测算主页'!B9*'测算主页'!B15*1000*'测算主页'!B19/SQRT(0.92))*'测算主页'!B27/10000 | G50: =(('测算主页'!B9+'测算主页'!B11*(1+A50))*'测算主页'!B15*1000*'测算主页'!B19*SQRT(0.94)-'测算主页'!B9*'测算主页'!B15*1000*'测算主页'!B19/SQRT(0.94))*'测算主页'!B27/10000 | H50: =(('测算主页'!B9+'测算主页'!B11*(1+A50))*'测算主页'!B15*1000*'测算主页'!B19*SQRT(0.96)-'测算主页'!B9*'测算主页'!B15*1000*'测算主页'!B19/SQRT(0.96))*'测算主页'!B27/10000
A51: +10% | B51: =(('测算主页'!B9+'测算主页'!B11*(1+A51))*'测算主页'!B15*1000*'测算主页'!B19*SQRT(0.84)-'测算主页'!B9*'测算主页'!B15*1000*'测算主页'!B19/SQRT(0.84))*'测算主页'!B27/10000 | C51: =(('测算主页'!B9+'测算主页'!B11*(1+A51))*'测算主页'!B15*1000*'测算主页'!B19*SQRT(0.86)-'测算主页'!B9*'测算主页'!B15*1000*'测算主页'!B19/SQRT(0.86))*'测算主页'!B27/10000 | D51: =(('测算主页'!B9+'测算主页'!B11*(1+A51))*'测算主页'!B15*1000*'测算主页'!B19*SQRT(0.88)-'测算主页'!B9*'测算主页'!B15*1000*'测算主页'!B19/SQRT(0.88))*'测算主页'!B27/10000 | E51: =(('测算主页'!B9+'测算主页'!B11*(1+A51))*'测算主页'!B15*1000*'测算主页'!B19*SQRT(0.9)-'测算主页'!B9*'测算主页'!B15*1000*'测算主页'!B19/SQRT(0.9))*'测算主页'!B27/10000 | F51: =(('测算主页'!B9+'测算主页'!B11*(1+A51))*'测算主页'!B15*1000*'测算主页'!B19*SQRT(0.92)-'测算主页'!B9*'测算主页'!B15*1000*'测算主页'!B19/SQRT(0.92))*'测算主页'!B27/10000 | G51: =(('测算主页'!B9+'测算主页'!B11*(1+A51))*'测算主页'!B15*1000*'测算主页'!B19*SQRT(0.94)-'测算主页'!B9*'测算主页'!B15*1000*'测算主页'!B19/SQRT(0.94))*'测算主页'!B27/10000 | H51: =(('测算主页'!B9+'测算主页'!B11*(1+A51))*'测算主页'!B15*1000*'测算主页'!B19*SQRT(0.96)-'测算主页'!B9*'测算主页'!B15*1000*'测算主页'!B19/SQRT(0.96))*'测算主页'!B27/10000
A52: +15% | B52: =(('测算主页'!B9+'测算主页'!B11*(1+A52))*'测算主页'!B15*1000*'测算主页'!B19*SQRT(0.84)-'测算主页'!B9*'测算主页'!B15*1000*'测算主页'!B19/SQRT(0.84))*'测算主页'!B27/10000 | C52: =(('测算主页'!B9+'测算主页'!B11*(1+A52))*'测算主页'!B15*1000*'测算主页'!B19*SQRT(0.86)-'测算主页'!B9*'测算主页'!B15*1000*'测算主页'!B19/SQRT(0.86))*'测算主页'!B27/10000 | D52: =(('测算主页'!B9+'测算主页'!B11*(1+A52))*'测算主页'!B15*1000*'测算主页'!B19*SQRT(0.88)-'测算主页'!B9*'测算主页'!B15*1000*'测算主页'!B19/SQRT(0.88))*'测算主页'!B27/10000 | E52: =(('测算主页'!B9+'测算主页'!B11*(1+A52))*'测算主页'!B15*1000*'测算主页'!B19*SQRT(0.9)-'测算主页'!B9*'测算主页'!B15*1000*'测算主页'!B19/SQRT(0.9))*'测算主页'!B27/10000 | F52: =(('测算主页'!B9+'测算主页'!B11*(1+A52))*'测算主页'!B15*1000*'测算主页'!B19*SQRT(0.92)-'测算主页'!B9*'测算主页'!B15*1000*'测算主页'!B19/SQRT(0.92))*'测算主页'!B27/10000 | G52: =(('测算主页'!B9+'测算主页'!B11*(1+A52))*'测算主页'!B15*1000*'测算主页'!B19*SQRT(0.94)-'测算主页'!B9*'测算主页'!B15*1000*'测算主页'!B19/SQRT(0.94))*'测算主页'!B27/10000 | H52: =(('测算主页'!B9+'测算主页'!B11*(1+A52))*'测算主页'!B15*1000*'测算主页'!B19*SQRT(0.96)-'测算主页'!B9*'测算主页'!B15*1000*'测算主页'!B19/SQRT(0.96))*'测算主页'!B27/10000
A53: +20% | B53: =(('测算主页'!B9+'测算主页'!B11*(1+A53))*'测算主页'!B15*1000*'测算主页'!B19*SQRT(0.84)-'测算主页'!B9*'测算主页'!B15*1000*'测算主页'!B19/SQRT(0.84))*'测算主页'!B27/10000 | C53: =(('测算主页'!B9+'测算主页'!B11*(1+A53))*'测算主页'!B15*1000*'测算主页'!B19*SQRT(0.86)-'测算主页'!B9*'测算主页'!B15*1000*'测算主页'!B19/SQRT(0.86))*'测算主页'!B27/10000 | D53: =(('测算主页'!B9+'测算主页'!B11*(1+A53))*'测算主页'!B15*1000*'测算主页'!B19*SQRT(0.88)-'测算主页'!B9*'测算主页'!B15*1000*'测算主页'!B19/SQRT(0.88))*'测算主页'!B27/10000 | E53: =(('测算主页'!B9+'测算主页'!B11*(1+A53))*'测算主页'!B15*1000*'测算主页'!B19*SQRT(0.9)-'测算主页'!B9*'测算主页'!B15*1000*'测算主页'!B19/SQRT(0.9))*'测算主页'!B27/10000 | F53: =(('测算主页'!B9+'测算主页'!B11*(1+A53))*'测算主页'!B15*1000*'测算主页'!B19*SQRT(0.92)-'测算主页'!B9*'测算主页'!B15*1000*'测算主页'!B19/SQRT(0.92))*'测算主页'!B27/10000 | G53: =(('测算主页'!B9+'测算主页'!B11*(1+A53))*'测算主页'!B15*1000*'测算主页'!B19*SQRT(0.94)-'测算主页'!B9*'测算主页'!B15*1000*'测算主页'!B19/SQRT(0.94))*'测算主页'!B27/10000 | H53: =(('测算主页'!B9+'测算主页'!B11*(1+A53))*'测算主页'!B15*1000*'测算主页'!B19*SQRT(0.96)-'测算主页'!B9*'测算主页'!B15*1000*'测算主页'!B19/SQRT(0.96))*'测算主页'!B27/10000
A54: ← 价差越大→毛利越高

Sheet 情景分析
A1: 三情景对比分析：乐观 / 基准 / 悲观
A2: 多变量同时变化，评估不同市场环境下的项目收益弹性
A4: 参数 | B4: 乐观情景 | C4: 基准情景 | D4: 悲观情景 | E4: 乐观vs基准 | F4: 悲观vs基准
A5: 峰段电价（元/kWh） | B5: 1.32 | C5: 1.2 | D5: 1.08 | E5: 0.1 | F5: -0.1
A6: 谷段电价（元/kWh） | B6: 0.27 | C6: 0.3 | D6: 0.33 | E6: -0.1 | F6: 0.1
A7: 峰谷价差（元/kWh） | B7: 1.05 | C7: 0.9 | D7: 0.75 | E7: 0.16666667 | F7: -0.16666667
A8: 充放电效率 | B8: 0.93 | C8: 0.9 | D8: 0.86 | E8: 0.033333333 | F8: -0.044444444
A9: 单位投资（元/Wh） | B9: 1.5 | C9: 1.8 | D9: 2.1 | E9: -0.16666667 | F9: 0.16666667
A10: 年衰减率 | B10: 0.015 | C10: 0.02 | D10: 0.025 | E10: -0.25 | F10: 0.25
A11: 年运营天数 | B11: 350 | C11: 330 | D11: 300 | E11: 0.060606061 | F11: -0.090909091
A12: 折现率 | B12: 0.06 | C12: 0.08 | D12: 0.1 | E12: -0.25 | F12: 0.25
A14: 财务指标对比
A15: 指标 | B15: 乐观情景 | C15: 基准情景 | D15: 悲观情景 | E15: 乐观vs基准 | F15: 悲观vs基准
A16: 初始投资（万元） | B16: 15000 | C16: 18000 | D16: 21000 | E16: -0.16666667 | F16: 0.16666667
A17: 第1年毛利（万元） | B17: 3475.4473 | C17: 2713.2342 | D17: 1937.1079 | E17: 0.28092417 | F17: -0.28605208
A18: 年运维费（万元） | B18: 300 | C18: 360 | D18: 420 | E18: -0.16666667 | F18: 0.16666667
A19: NPV（万元） | B19: 6885.2116 | C19: -3551.8693 | D19: -12722.2 | E19: 2.9384755 | F19: -2.5818323
A20: IRR | B20: 0.15146488 | C20: 0.032277032 | D20: -0.080827313 | E20: 0.11918785 | F20: -0.11310435
A21: 动态回收期（年） | B21: 4.0139381 | C21: 10 | D21: 10 | E21: N/A | F21: N/A
B23: 乐观 | C23: 基准 | D23: 悲观
A24: NPV | B24: 6885.2116 | C24: -3551.8693 | D24: -12722.2
B41: 乐观 | C41: 基准 | D41: 悲观
A42: IRR | B42: 0.15146488 | C42: 0.032277032 | D42: -0.080827313
